2025-08-10 16:41:48,203 - INFO - Loading model from URI: models:/IrisClassifier/8
2025-08-10 16:41:52,139 - INFO - Loaded model IrisClassifier version 8
2025-08-10 16:42:10,538 - INFO - Loading model from URI: models:/IrisClassifier/8
2025-08-10 16:42:14,386 - INFO - Loaded model IrisClassifier version 8
2025-08-10 16:47:08,638 - INFO - Request: {'sepal_length': 5.1, 'sepal_width': 3.5, 'petal_length': 1.4, 'petal_width': 0.2}
2025-08-10 16:47:08,645 - ERROR - Prediction error: Failed to enforce schema of data '   sepal_length  sepal_width  petal_length  petal_width
0           5.1          3.5           1.4          0.2' with schema '['sepal length (cm)': double (required), 'sepal width (cm)': double (required), 'petal length (cm)': double (required), 'petal width (cm)': double (required)]'. Error: Model is missing inputs ['sepal length (cm)', 'sepal width (cm)', 'petal length (cm)', 'petal width (cm)']. Note that there were extra inputs: ['petal_length', 'sepal_width', 'sepal_length', 'petal_width'].
Traceback (most recent call last):
  File "C:\Users\samulya\AppData\Local\anaconda3\Lib\site-packages\mlflow\pyfunc\__init__.py", line 734, in _validate_prediction_input
    data = _enforce_schema(data, input_schema, flavor)
           ^^^^^^^^^^^^^^^^^^^^^^^^^^^^^^^^^^^^^^^^^^^
  File "C:\Users\samulya\AppData\Local\anaconda3\Lib\site-packages\mlflow\models\utils.py", line 1268, in _enforce_schema
    raise MlflowException(message)
mlflow.exceptions.MlflowException: Model is missing inputs ['sepal length (cm)', 'sepal width (cm)', 'petal length (cm)', 'petal width (cm)']. Note that there were extra inputs: ['petal_length', 'sepal_width', 'sepal_length', 'petal_width'].

During handling of the above exception, another exception occurred:

Traceback (most recent call last):
  File "C:\Users\samulya\Desktop\Academics\MLOPS\Assignment\src\api\app.py", line 124, in predict
    preds = model.predict(input_df)
            ^^^^^^^^^^^^^^^^^^^^^^^
  File "C:\Users\samulya\AppData\Local\anaconda3\Lib\site-packages\mlflow\pyfunc\__init__.py", line 845, in predict
    return self._predict(data, params)
           ^^^^^^^^^^^^^^^^^^^^^^^^^^^
  File "C:\Users\samulya\AppData\Local\anaconda3\Lib\site-packages\mlflow\pyfunc\__init__.py", line 884, in _predict
    data, params = _validate_prediction_input(
                   ^^^^^^^^^^^^^^^^^^^^^^^^^^^
  File "C:\Users\samulya\AppData\Local\anaconda3\Lib\site-packages\mlflow\pyfunc\__init__.py", line 745, in _validate_prediction_input
    raise MlflowException.invalid_parameter_value(message)
mlflow.exceptions.MlflowException: Failed to enforce schema of data '   sepal_length  sepal_width  petal_length  petal_width
0           5.1          3.5           1.4          0.2' with schema '['sepal length (cm)': double (required), 'sepal width (cm)': double (required), 'petal length (cm)': double (required), 'petal width (cm)': double (required)]'. Error: Model is missing inputs ['sepal length (cm)', 'sepal width (cm)', 'petal length (cm)', 'petal width (cm)']. Note that there were extra inputs: ['petal_length', 'sepal_width', 'sepal_length', 'petal_width'].
2025-08-10 16:47:10,436 - INFO - Request: {'sepal_length': 5.1, 'sepal_width': 3.5, 'petal_length': 1.4, 'petal_width': 0.2}
2025-08-10 16:47:10,443 - ERROR - Prediction error: Failed to enforce schema of data '   sepal_length  sepal_width  petal_length  petal_width
0           5.1          3.5           1.4          0.2' with schema '['sepal length (cm)': double (required), 'sepal width (cm)': double (required), 'petal length (cm)': double (required), 'petal width (cm)': double (required)]'. Error: Model is missing inputs ['sepal length (cm)', 'sepal width (cm)', 'petal length (cm)', 'petal width (cm)']. Note that there were extra inputs: ['petal_length', 'sepal_width', 'sepal_length', 'petal_width'].
Traceback (most recent call last):
  File "C:\Users\samulya\AppData\Local\anaconda3\Lib\site-packages\mlflow\pyfunc\__init__.py", line 734, in _validate_prediction_input
    data = _enforce_schema(data, input_schema, flavor)
           ^^^^^^^^^^^^^^^^^^^^^^^^^^^^^^^^^^^^^^^^^^^
  File "C:\Users\samulya\AppData\Local\anaconda3\Lib\site-packages\mlflow\models\utils.py", line 1268, in _enforce_schema
    raise MlflowException(message)
mlflow.exceptions.MlflowException: Model is missing inputs ['sepal length (cm)', 'sepal width (cm)', 'petal length (cm)', 'petal width (cm)']. Note that there were extra inputs: ['petal_length', 'sepal_width', 'sepal_length', 'petal_width'].

During handling of the above exception, another exception occurred:

Traceback (most recent call last):
  File "C:\Users\samulya\Desktop\Academics\MLOPS\Assignment\src\api\app.py", line 124, in predict
    preds = model.predict(input_df)
            ^^^^^^^^^^^^^^^^^^^^^^^
  File "C:\Users\samulya\AppData\Local\anaconda3\Lib\site-packages\mlflow\pyfunc\__init__.py", line 845, in predict
    return self._predict(data, params)
           ^^^^^^^^^^^^^^^^^^^^^^^^^^^
  File "C:\Users\samulya\AppData\Local\anaconda3\Lib\site-packages\mlflow\pyfunc\__init__.py", line 884, in _predict
    data, params = _validate_prediction_input(
                   ^^^^^^^^^^^^^^^^^^^^^^^^^^^
  File "C:\Users\samulya\AppData\Local\anaconda3\Lib\site-packages\mlflow\pyfunc\__init__.py", line 745, in _validate_prediction_input
    raise MlflowException.invalid_parameter_value(message)
mlflow.exceptions.MlflowException: Failed to enforce schema of data '   sepal_length  sepal_width  petal_length  petal_width
0           5.1          3.5           1.4          0.2' with schema '['sepal length (cm)': double (required), 'sepal width (cm)': double (required), 'petal length (cm)': double (required), 'petal width (cm)': double (required)]'. Error: Model is missing inputs ['sepal length (cm)', 'sepal width (cm)', 'petal length (cm)', 'petal width (cm)']. Note that there were extra inputs: ['petal_length', 'sepal_width', 'sepal_length', 'petal_width'].
